Workbook

Sheet NPCs bc45871df08a46b3ae7d8e083e
A1: ﻿Name | B1: Character Type | C1: Class | D1: Strength | E1: Agility | F1: Speed | G1: Abilities | H1: Condition | I1: Defense | J1: Hit Points | K1: Mind | L1: Race | M1: Adjective | N1: Locations | O1: Related Quests
A2: Aarya | B2: NPC, Shop Owner | C2: Robo-tech | D2: 7 | E2: 18 | F2: 4 | G2: Speedster | I2: 1 | J2: 39 | K2: 14 | L2: Goblin | M2: Optimistic | N2: Aarya's Weapon Shop (https://www.notion.so/Aarya-s-Weapon-Shop-14508c44b7d7801698cbffabaa2ccff3?pvs=21)
A3: Abba | B3: NPC | C3: Botanist | D3: 17 | E3: 5 | F3: 4 | G3: Observant | I3: 2 | J3: 36 | K3: 21 | L3: Ogre | M3: Macho
A4: Abbey | B4: NPC, Rainbow Guard | C4: Botanist | D4: 24 | E4: 4 | F4: 3 | G4: Unhelpful | I4: 3 | J4: 134 | K4: 23 | L4: Bastian | M4: Elderly
A5: Abella | B5: NPC | C5: Angler | D5: 9 | E5: 23 | F5: 2 | G5: Armstrong | I5: 19 | J5: 177 | K5: 6 | L5: Goblin | M5: Bleeding
A6: Abie | B6: NPC | C6: Angler | D6: 17 | E6: 19 | F6: 4 | G6: Talkative | I6: 20 | J6: 137 | K6: 17 | L6: Esparan | M6: Sensitive
A7: Adana | B7: NPC, Shop Worker | C7: Gymnast | D7: 2 | E7: 21 | F7: 6 | G7: Sweet Liar | I7: 20 | J7: 80 | K7: 3 | L7: Human | M7: Cautious
A8: Addeson | B8: NPC | C8: Writer | D8: 14 | E8: 16 | F8: 4 | G8: Armstrong | I8: 3 | J8: 24 | K8: 15 | L8: Fairy | M8: Elderly
A9: Addie | B9: NPC | C9: Time Caster | D9: 18 | E9: 19 | F9: 3 | G9: Sweet Liar | I9: 9 | J9: 3 | K9: 16 | L9: Luskin | M9: Macho
A10: Addy | B10: NPC | C10: Surgeon | D10: 25 | E10: 6 | F10: 6 | G10: Speedster | I10: 12 | J10: 53 | K10: 23 | L10: Technokin | M10: Serious
A11: Addyson | B11: NPC | C11: Artist | D11: 24 | E11: 22 | F11: 2 | G11: Sweet Liar | I11: 5 | J11: 189 | K11: 5 | L11: Ogre | M11: Pessimistic
A12: Adel | B12: NPC | C12: Artist | D12: 26 | E12: 4 | F12: 6 | G12: Armstrong | I12: 6 | J12: 99 | K12: 14 | L12: Luskin | M12: Scared
A13: Aden | B13: NPC | C13: Artist | D13: 23 | E13: 25 | F13: 5 | G13: Armstrong | I13: 4 | J13: 177 | K13: 9 | L13: Goblin | M13: Scared
A14: Adison | B14: NPC, Shop Worker | C14: Gymnast | D14: 14 | E14: 1 | F14: 6 | G14: Truth Seeker | I14: 17 | J14: 6 | K14: 12 | L14: Esparan | M14: Serious
... A24: Robin | B24: NPC, Quest, Sewer Dweller | C24: Angler | D24: 14 | E24: 16 | F24: 3 | G24: Nimble | I24: 2 | J24: 83 | K24: 25 | L24: Luskin | M24: Small
A25: Akari | B25: NPC, Shop Owner | C25: Angler | D25: 25 | E25: 5 | F25: 3 | G25: Talkative | I25: 3 | J25: 149 | K25: 12 | L25: Fairy | M25: Sensitive | N25: The Hut Shop (https://www.notion.so/The-Hut-Shop-ec01a27fd8414e7f8360a6b9eaab00fb?pvs=21)
A26: Akira | B26: NPC | C26: Gymnast | D26: 2 | E26: 7 | F26: 5 | G26: Talkative | I26: 14 | J26: 100 | K26: 5 | L26: Human | M26: Serious
A27: Akoni | B27: NPC | C27: Chef | D27: 15 | E27: 19 | F27: 3 | G27: Keen Eyes | I27: 2 | J27: 34 | K27: 12 | L27: Goblin | M27: Sensitive
A28: Al | B28: NPC | C28: Robo-tech | D28: 16 | E28: 23 | F28: 5 | G28: Truth Seeker | I28: 15 | J28: 155 | K28: 6 | L28: Goblin | M28: Scared
A29: Alaia | B29: NPC | C29: Robo-tech | D29: 24 | E29: 11 | F29: 3 | G29: Super Taster | I29: 13 | J29: 17 | K29: 7 | L29: Technokin | M29: Sensitive
A30: Alair | B30: NPC | C30: Angler | D30: 22 | E30: 17 | F30: 6 | G30: Truth Seeker | I30: 15 | J30: 100 | K30: 14 | L30: Human | M30: Sensitive
A31: Alaire | B31: NPC, Sewer Dweller, Shop Owner | C31: Preceptor | D31: 14 | E31: 6 | F31: 3 | G31: Observant | I31: 8 | J31: 64 | K31: 25 | L31: Luskin | M31: Sensitive
A32: Alasdair | B32: NPC | C32: Surgeon | D32: 12 | E32: 11 | F32: 4 | G32: Speedster | I32: 15 | J32: 83 | K32: 5 | L32: Ogre | M32: Serious
A33: Alaska | B33: NPC | C33: Writer | D33: 22 | E33: 23 | F33: 1 | G33: Nimble | I33: 20 | J33: 10 | K33: 21 | L33: Luskin | M33: Bleeding
A34: Alastair | B34: NPC, Shop Owner | C34: Time Caster | D34: 19 | E34: 5 | F34: 6 | G34: Truth Seeker | I34: 3 | J34: 123 | K34: 12 | L34: Esparan | M34: Pessimistic | N34: Alluring Bookshop (https://www.notion.so/Alluring-Bookshop-8bbc5b17d9b846bdb2f2b4f9610ecf84?pvs=21)
A35: Alba | B35: NPC | C35: Botanist | D35: 5 | E35: 16 | F35: 5 | G35: Talkative | I35: 12 | J35: 137 | K35: 15 | L35: Luskin | M35: Serious
A36: Alcie | B36: NPC | C36: Botanist | D36: 14 | E36: 12 | F36: 6 | G36: Speedster | I36: 11 | J36: 93 | K36: 10 | L36: Esparan | M36: Macho
A37: Alder | B37: NPC | C37: Gymnast | D37: 19 | E37: 21 | F37: 2 | G37: Unhelpful | I37: 11 | J37: 171 | K37: 6 | L37: Goblin | M37: Serious
A38: Alessi | B38: NPC | C38: Writer | D38: 9 | E38: 7 | F38: 2 | G38: Observant | I38: 17 | J38: 19 | K38: 17 | L38: Ethalins | M38: Scared
A39: Alex | B39: NPC, Shop Owner | C39: Chef | D39: 19 | E39: 4 | F39: 1 | G39: Observant | I39: 6 | J39: 67 | K39: 24 | L39: Esparan | M39: Macho | N39: Alex’s Mocho Shopo (https://www.notion.so/Alex-s-Mocho-Shopo-7a79cb80ce0c41938f358e26aa82b885?pvs=21) | O39: Eating competition (https://www.notion.so/Eating-competition-9bd94e59245140b291bac5993b2886f3?pvs=21)
A40: Alexandre | B40: NPC | C40: Animal Trainer | D40: 18 | E40: 20 | F40: 4 | G40: Truth Seeker | I40: 9 | J40: 94 | K40: 17 | L40: Human | M40: Serious
A41: Alexi | B41: NPC | C41: Writer | D41: 19 | E41: 9 | F41: 5 | G41: Stubborn | I41: 6 | J41: 126 | K41: 19 | L41: Esparan | M41: Cautious
A42: Alexis | B42: NPC, Shop Owner | C42: Time Caster | D42: 20 | E42: 4 | F42: 7 | G42: Speedster | I42: 20 | J42: 93 | K42: 7 | L42: Luskin | M42: Macho | N42: Information Station (https://www.notion.so/Information-Station-5b3d28a9933f48df95965281ebd8859b?pvs=21)
A43: Alexus | B43: NPC | C43: Angler | D43: 20 | E43: 6 | F43: 5 | G43: Nimble | I43: 17 | J43: 70 | K43: 11 | L43: Human | M43: Bleeding
A44: Alfa | B44: NPC, Shop Owner | C44: Surgeon | D44: 2 | E44: 18 | F44: 7 | G44: Truth Seeker | I44: 12 | J44: 80 | K44: 9 | L44: Luskin | M44: Pessimistic | N44: Alfa's Rare Pet Shop (https://www.notion.so/Alfa-s-Rare-Pet-Shop-73a93c8657c545f58f574003092e5787?pvs=21)
A45: Alika | B45: NPC | C45: Writer | D45: 8 | E45: 17 | F45: 5 | G45: Unhelpful | I45: 19 | J45: 107 | K45: 25 | L45: Goblin | M45: Serious
A46: Alin | B46: NPC | C46: Angler | D46: 12 | E46: 4 | F46: 2 | G46: Nimble | I46: 2 | J46: 181 | K46: 7 | L46: Ogre | M46: Serious
A47: Alison | B47: NPC, Shop Owner | C47: Botanist | D47: 18 | E47: 4 | F47: 6 | G47: Truth Seeker | I47: 3 | J47: 29 | K47: 18 | L47: Boktonian | M47: Macho | N47: Bubbling Brewery (https://www.notion.so/Bubbling-Brewery-6370bdc34f8e42bab03095026789036b?pvs=21)
A48: Alley | B48: NPC | C48: Time Caster | D48: 11 | E48: 23 | F48: 7 | G48: Speedster | I48: 11 | J48: 143 | K48: 24 | L48: Bastian | M48: Macho
A49: Allie | B49: NPC, Shop Owner | C49: Robo-tech | D49: 18 | E49: 5 | F49: 7 | G49: Keen Eyes | I49: 13 | J49: 21 | K49: 23 | L49: Fairy | M49: Strong | N49: Allie’s Specialties (https://www.notion.so/Allie-s-Specialties-061412b3b7ba40fd8a5f79388b356f02?pvs=21)
...

Sheet Sheet1
A1: {"id": | B1: 51 | C1: ,"name":" | D1: ='NPCs bc45871df08a46b3ae7d8e083e'!A3 -> Abba | E1: ,note":"","pages":[{"conditions":{"actorId":1,"actorValid":false,"itemId":1,"itemValid":false,"selfSwitchCh":"A","selfSwitchValid":false,"switch1Id":1,"switch1Valid":false,"switch2Id":1,"switch2Valid":false,"variableId":1,"variableValid":false,"variableValue":0},"directionFix":true,"image":{"tileId":0,"characterName":"People/04-Mage","direction":2,"pattern":0,"characterIndex":0},"list":[{"code":108,"indent":0,"parameters":["iconOnMinimap:minimapIcon_Evil7"]},{"code":108,"indent":0,"parameters":["<ABS: | F1: =B1 -> 51 | G1: >"]},{"code":108,"indent":0,"parameters":["<label: NPC>"]},{"code":357,"indent":0,"parameters":["Alpha_ABSZ","ABSEventSettings","ABS Enemy Configurate",{"MainGroup":"","viewRadius":"5","returnRadius":"12","noMoveInBattle":"false","noApproach":"true","onDeath":"","onSeeTarget":"","onHit":"","expVar":"0","autoExp":"false","notAgressive":"true","teamId":"2","onDeathVar":"0","saveHp":"false","MapGroup":"","shatterEffect":"true","deadSwitch":"0","eraseOnDead":"true","heavy":"false","weaponMotionType":"0","lootDropOnDeath":"false","VisualGroup":"","UIInfo":"true","faceName":"","faceIndex":"0","miniHpGaugeStyle":"","AnimationGroup":"","hitAnimationId":"1"}]},{"code":657,"indent":0,"parameters":["Main Group = "]},{"code":657,"indent":0,"parameters":["View Radius = 5"]},{"code":657,"indent":0,"parameters":["Return Radius = 12"]},{"code":657,"indent":0,"parameters":["No Move in Battle = false"]},{"code":657,"indent":0,"parameters":["No Approach Target = true"]},{"code":657,"indent":0,"parameters":["On Death = "]},{"code":657,"indent":0,"parameters":["On See Target = "]},{"code":657,"indent":0,"parameters":["On Hit = "]},{"code":657,"indent":0,"parameters":["Exp Variable = 0"]},{"code":657,"indent":0,"parameters":["Auto Exp = false"]},{"code":657,"indent":0,"parameters":["Not Agressive = true"]},{"code":657,"indent":0,"parameters":["Team ID = 2"]},{"code":657,"indent":0,"parameters":["Death Variable = 0"]},{"code":657,"indent":0,"parameters":["Save HP = false"]},{"code":657,"indent":0,"parameters":["Map Group = "]},{"code":657,"indent":0,"parameters":["Shatter Effect? = true"]},{"code":657,"indent":0,"parameters":["Dead Switch = 0"]},{"code":657,"indent":0,"parameters":["Erase on Dead? = true"]},{"code":657,"indent":0,"parameters":["Is heavy = false"]},{"code":657,"indent":0,"parameters":["Weapon Motion Type = 0"]},{"code":657,"indent":0,"parameters":["Drop Loot = false"]},{"code":657,"indent":0,"parameters":["Visual Group = "]},{"code":657,"indent":0,"parameters":["Show UI Info? = true"]},{"code":657,"indent":0,"parameters":["Face Name = "]},{"code":657,"indent":0,"parameters":["Face Index = 0"]},{"code":657,"indent":0,"parameters":["Mini HP Gauge Style = "]},{"code":657,"indent":0,"parameters":["Animation Group = "]},{"code":657,"indent":0,"parameters":["Hit Animation = 1"]},{"code":101,"indent":0,"parameters":["ds_face01-02",5,0,2,""]},{"code":401,"indent":0,"parameters":["Hi I'm | H1: =D1 -> Abba | I1: ."]},{"code":0,"indent":0,"parameters":[]}],"moveFrequency":3,"moveRoute":{"list":[{"code":0,"parameters":[]}],"repeat":true,"skippable":false,"wait":false},"moveSpeed":3,"moveType":0,"priorityType":1,"stepAnime":false,"through":false,"trigger":0,"walkAnime":true},{"conditions":{"actorId":1,"actorValid":false,"itemId":1,"itemValid":false,"selfSwitchCh":"A","selfSwitchValid":true,"switch1Id":1,"switch1Valid":false,"switch2Id":1,"switch2Valid":false,"variableId":1,"variableValid":false,"variableValue":0},"directionFix":false,"image":{"tileId":0,"characterName":"People/04-Mage","direction":2,"pattern":0,"characterIndex":0},"list":[{"code":108,"indent":0,"parameters":["iconOnMinimap:minimapIcon_Evil7"]},{"code":108,"indent":0,"parameters":["<ABS: | J1: =B1 -> 51 | K1: >"]},{"code":108,"indent":0,"parameters":["<label: NPC>"]},{"code":357,"indent":0,"parameters":["Alpha_ABSZ","ABSEventSettings","ABS Enemy Configurate",{"MainGroup":"","viewRadius":"5","returnRadius":"12","noMoveInBattle":"false","noApproach":"true","onDeath":"","onSeeTarget":"","onHit":"","expVar":"0","autoExp":"false","notAgressive":"true","teamId":"2","onDeathVar":"0","saveHp":"false","MapGroup":"","shatterEffect":"true","deadSwitch":"0","eraseOnDead":"true","heavy":"false","weaponMotionType":"0","lootDropOnDeath":"false","VisualGroup":"","UIInfo":"true","faceName":"","faceIndex":"0","miniHpGaugeStyle":"","AnimationGroup":"","hitAnimationId":"1"}]},{"code":657,"indent":0,"parameters":["Main Group = "]},{"code":657,"indent":0,"parameters":["View Radius = 5"]},{"code":657,"indent":0,"parameters":["Return Radius = 12"]},{"code":657,"indent":0,"parameters":["No Move in Battle = false"]},{"code":657,"indent":0,"parameters":["No Approach Target = true"]},{"code":657,"indent":0,"parameters":["On Death = "]},{"code":657,"indent":0,"parameters":["On See Target = "]},{"code":657,"indent":0,"parameters":["On Hit = "]},{"code":657,"indent":0,"parameters":["Exp Variable = 0"]},{"code":657,"indent":0,"parameters":["Auto Exp = false"]},{"code":657,"indent":0,"parameters":["Not Agressive = true"]},{"code":657,"indent":0,"parameters":["Team ID = 2"]},{"code":657,"indent":0,"parameters":["Death Variable = 0"]},{"code":657,"indent":0,"parameters":["Save HP = false"]},{"code":657,"indent":0,"parameters":["Map Group = "]},{"code":657,"indent":0,"parameters":["Shatter Effect? = true"]},{"code":657,"indent":0,"parameters":["Dead Switch = 0"]},{"code":657,"indent":0,"parameters":["Erase on Dead? = true"]},{"code":657,"indent":0,"parameters":["Is heavy = false"]},{"code":657,"indent":0,"parameters":["Weapon Motion Type = 0"]},{"code":657,"indent":0,"parameters":["Drop Loot = false"]},{"code":657,"indent":0,"parameters":["Visual Group = "]},{"code":657,"indent":0,"parameters":["Show UI Info? = true"]},{"code":657,"indent":0,"parameters":["Face Name = "]},{"code":657,"indent":0,"parameters":["Face Index = 0"]},{"code":657,"indent":0,"parameters":["Mini HP Gauge Style = "]},{"code":657,"indent":0,"parameters":["Animation Group = "]},{"code":657,"indent":0,"parameters":["Hit Animation = 1"]},{"code":101,"indent":0,"parameters":["People4",5,0,2,""]},{"code":401,"indent":0,"parameters":["Hi I'm | L1: =D1 -> Abba | M1: ."]},{"code":0,"indent":0,"parameters":[]}],"moveFrequency":3,"moveRoute":{"list":[{"code":0,"parameters":[]}],"repeat":true,"skippable":false,"wait":false},"moveSpeed":3,"moveType":0,"priorityType":1,"stepAnime":false,"through":false,"trigger":0,"walkAnime":true},{"conditions":{"actorId":1,"actorValid":false,"itemId":1,"itemValid":false,"selfSwitchCh":"B","selfSwitchValid":true,"switch1Id":1,"switch1Valid":false,"switch2Id":1,"switch2Valid":false,"variableId":1,"variableValid":false,"variableValue":0},"directionFix":false,"image":{"tileId":0,"characterName":"People/04-Mage","direction":2,"pattern":0,"characterIndex":0},"list":[{"code":108,"indent":0,"parameters":["iconOnMinimap:minimapIcon_Evil7"]},{"code":108,"indent":0,"parameters":["<ABS: | N1: =B1 -> 51 | O1: >"]},{"code":108,"indent":0,"parameters":["<label: NPC>"]},{"code":357,"indent":0,"parameters":["Alpha_ABSZ","ABSEventSettings","ABS Enemy Configurate",{"MainGroup":"","viewRadius":"5","returnRadius":"12","noMoveInBattle":"false","noApproach":"true","onDeath":"","onSeeTarget":"","onHit":"","expVar":"0","autoExp":"false","notAgressive":"true","teamId":"2","onDeathVar":"0","saveHp":"false","MapGroup":"","shatterEffect":"true","deadSwitch":"0","eraseOnDead":"true","heavy":"false","weaponMotionType":"0","lootDropOnDeath":"false","VisualGroup":"","UIInfo":"true","faceName":"","faceIndex":"0","miniHpGaugeStyle":"","AnimationGroup":"","hitAnimationId":"1"}]},{"code":657,"indent":0,"parameters":["Main Group = "]},{"code":657,"indent":0,"parameters":["View Radius = 5"]},{"code":657,"indent":0,"parameters":["Return Radius = 12"]},{"code":657,"indent":0,"parameters":["No Move in Battle = false"]},{"code":657,"indent":0,"parameters":["No Approach Target = true"]},{"code":657,"indent":0,"parameters":["On Death = "]},{"code":657,"indent":0,"parameters":["On See Target = "]},{"code":657,"indent":0,"parameters":["On Hit = "]},{"code":657,"indent":0,"parameters":["Exp Variable = 0"]},{"code":657,"indent":0,"parameters":["Auto Exp = false"]},{"code":657,"indent":0,"parameters":["Not Agressive = true"]},{"code":657,"indent":0,"parameters":["Team ID = 2"]},{"code":657,"indent":0,"parameters":["Death Variable = 0"]},{"code":657,"indent":0,"parameters":["Save HP = false"]},{"code":657,"indent":0,"parameters":["Map Group = "]},{"code":657,"indent":0,"parameters":["Shatter Effect? = true"]},{"code":657,"indent":0,"parameters":["Dead Switch = 0"]},{"code":657,"indent":0,"parameters":["Erase on Dead? = true"]},{"code":657,"indent":0,"parameters":["Is heavy = false"]},{"code":657,"indent":0,"parameters":["Weapon Motion Type = 0"]},{"code":657,"indent":0,"parameters":["Drop Loot = false"]},{"code":657,"indent":0,"parameters":["Visual Group = "]},{"code":657,"indent":0,"parameters":["Show UI Info? = true"]},{"code":657,"indent":0,"parameters":["Face Name = "]},{"code":657,"indent":0,"parameters":["Face Index = 0"]},{"code":657,"indent":0,"parameters":["Mini HP Gauge Style = "]},{"code":657,"indent":0,"parameters":["Animation Group = "]},{"code":657,"indent":0,"parameters":["Hit Animation = 1"]},{"code":101,"indent":0,"parameters":["People4",5,0,2,""]},{"code":401,"indent":0,"parameters":["Hi I'm | P1: =D1 -> Abba | Q1: ."]},{"code":0,"indent":0,"parameters":[]}],"moveFrequency":3,"moveRoute":{"list":[{"code":0,"parameters":[]}],"repeat":true,"skippable":false,"wait":false},"moveSpeed":3,"moveType":0,"priorityType":1,"stepAnime":false,"through":false,"trigger":0,"walkAnime":true},{"conditions":{"actorId":1,"actorValid":false,"itemId":1,"itemValid":false,"selfSwitchCh":"C","selfSwitchValid":true,"switch1Id":1,"switch1Valid":false,"switch2Id":1,"switch2Valid":false,"variableId":1,"variableValid":false,"variableValue":0},"directionFix":false,"image":{"tileId":0,"characterName":"People/04-Mage","direction":2,"pattern":0,"characterIndex":0},"list":[{"code":108,"indent":0,"parameters":["iconOnMinimap:minimapIcon_Evil7"]},{"code":108,"indent":0,"parameters":["<ABS: | R1: =B1 -> 51 | S1: >"]},{"code":108,"indent":0,"parameters":["<label: NPC>"]},{"code":357,"indent":0,"parameters":["Alpha_ABSZ","ABSEventSettings","ABS Enemy Configurate",{"MainGroup":"","viewRadius":"5","returnRadius":"12","noMoveInBattle":"false","noApproach":"true","onDeath":"","onSeeTarget":"","onHit":"","expVar":"0","autoExp":"false","notAgressive":"true","teamId":"2","onDeathVar":"0","saveHp":"false","MapGroup":"","shatterEffect":"true","deadSwitch":"0","eraseOnDead":"true","heavy":"false","weaponMotionType":"0","lootDropOnDeath":"false","VisualGroup":"","UIInfo":"true","faceName":"","faceIndex":"0","miniHpGaugeStyle":"","AnimationGroup":"","hitAnimationId":"1"}]},{"code":657,"indent":0,"parameters":["Main Group = "]},{"code":657,"indent":0,"parameters":["View Radius = 5"]},{"code":657,"indent":0,"parameters":["Return Radius = 12"]},{"code":657,"indent":0,"parameters":["No Move in Battle = false"]},{"code":657,"indent":0,"parameters":["No Approach Target = true"]},{"code":657,"indent":0,"parameters":["On Death = "]},{"code":657,"indent":0,"parameters":["On See Target = "]},{"code":657,"indent":0,"parameters":["On Hit = "]},{"code":657,"indent":0,"parameters":["Exp Variable = 0"]},{"code":657,"indent":0,"parameters":["Auto Exp = false"]},{"code":657,"indent":0,"parameters":["Not Agressive = true"]},{"code":657,"indent":0,"parameters":["Team ID = 2"]},{"code":657,"indent":0,"parameters":["Death Variable = 0"]},{"code":657,"indent":0,"parameters":["Save HP = false"]},{"code":657,"indent":0,"parameters":["Map Group = "]},{"code":657,"indent":0,"parameters":["Shatter Effect? = true"]},{"code":657,"indent":0,"parameters":["Dead Switch = 0"]},{"code":657,"indent":0,"parameters":["Erase on Dead? = true"]},{"code":657,"indent":0,"parameters":["Is heavy = false"]},{"code":657,"indent":0,"parameters":["Weapon Motion Type = 0"]},{"code":657,"indent":0,"parameters":["Drop Loot = false"]},{"code":657,"indent":0,"parameters":["Visual Group = "]},{"code":657,"indent":0,"parameters":["Show UI Info? = true"]},{"code":657,"indent":0,"parameters":["Face Name = "]},{"code":657,"indent":0,"parameters":["Face Index = 0"]},{"code":657,"indent":0,"parameters":["Mini HP Gauge Style = "]},{"code":657,"indent":0,"parameters":["Animation Group = "]},{"code":657,"indent":0,"parameters":["Hit Animation = 1"]},{"code":101,"indent":0,"parameters":["People4",5,0,2,""]},{"code":401,"indent":0,"parameters":["Hi I'm | T1: =D1 -> Abba | U1: ."]},{"code":0,"indent":0,"parameters":[]}],"moveFrequency":3,"moveRoute":{"list":[{"code":0,"parameters":[]}],"repeat":true,"skippable":false,"wait":false},"moveSpeed":3,"moveType":0,"priorityType":1,"stepAnime":false,"through":false,"trigger":0,"walkAnime":true},{"conditions":{"actorId":1,"actorValid":false,"itemId":1,"itemValid":false,"selfSwitchCh":"D","selfSwitchValid":true,"switch1Id":1,"switch1Valid":false,"switch2Id":1,"switch2Valid":false,"variableId":1,"variableValid":false,"variableValue":0},"directionFix":false,"image":{"tileId":0,"characterName":"People/04-Mage","direction":2,"pattern":0,"characterIndex":0},"list":[{"code":108,"indent":0,"parameters":["iconOnMinimap:minimapIcon_Evil7"]},{"code":108,"indent":0,"parameters":["<ABS: | V1: =B1 -> 51 | W1: >"]},{"code":108,"indent":0,"parameters":["<label: NPC>"]},{"code":357,"indent":0,"parameters":["Alpha_ABSZ","ABSEventSettings","ABS Enemy Configurate",{"MainGroup":"","viewRadius":"5","returnRadius":"12","noMoveInBattle":"false","noApproach":"true","onDeath":"","onSeeTarget":"","onHit":"","expVar":"0","autoExp":"false","notAgressive":"true","teamId":"2","onDeathVar":"0","saveHp":"false","MapGroup":"","shatterEffect":"true","deadSwitch":"0","eraseOnDead":"true","heavy":"false","weaponMotionType":"0","lootDropOnDeath":"false","VisualGroup":"","UIInfo":"true","faceName":"","faceIndex":"0","miniHpGaugeStyle":"","AnimationGroup":"","hitAnimationId":"1"}]},{"code":657,"indent":0,"parameters":["Main Group = "]},{"code":657,"indent":0,"parameters":["View Radius = 5"]},{"code":657,"indent":0,"parameters":["Return Radius = 12"]},{"code":657,"indent":0,"parameters":["No Move in Battle = false"]},{"code":657,"indent":0,"parameters":["No Approach Target = true"]},{"code":657,"indent":0,"parameters":["On Death = "]},{"code":657,"indent":0,"parameters":["On See Target = "]},{"code":657,"indent":0,"parameters":["On Hit = "]},{"code":657,"indent":0,"parameters":["Exp Variable = 0"]},{"code":657,"indent":0,"parameters":["Auto Exp = false"]},{"code":657,"indent":0,"parameters":["Not Agressive = true"]},{"code":657,"indent":0,"parameters":["Team ID = 2"]},{"code":657,"indent":0,"parameters":["Death Variable = 0"]},{"code":657,"indent":0,"parameters":["Save HP = false"]},{"code":657,"indent":0,"parameters":["Map Group = "]},{"code":657,"indent":0,"parameters":["Shatter Effect? = true"]},{"code":657,"indent":0,"parameters":["Dead Switch = 0"]},{"code":657,"indent":0,"parameters":["Erase on Dead? = true"]},{"code":657,"indent":0,"parameters":["Is heavy = false"]},{"code":657,"indent":0,"parameters":["Weapon Motion Type = 0"]},{"code":657,"indent":0,"parameters":["Drop Loot = false"]},{"code":657,"indent":0,"parameters":["Visual Group = "]},{"code":657,"indent":0,"parameters":["Show UI Info? = true"]},{"code":657,"indent":0,"parameters":["Face Name = "]},{"code":657,"indent":0,"parameters":["Face Index = 0"]},{"code":657,"indent":0,"parameters":["Mini HP Gauge Style = "]},{"code":657,"indent":0,"parameters":["Animation Group = "]},{"code":657,"indent":0,"parameters":["Hit Animation = 1"]},{"code":101,"indent":0,"parameters":["People4",5,0,2,""]},{"code":401,"indent":0,"parameters":["Hi I'm | X1: =D1 -> Abba | Y1: ."]},{"code":0,"indent":0,"parameters":[]}],"moveFrequency":3,"moveRoute":{"list":[{"code":0,"parameters":[]}],"repeat":true,"skippable":false,"wait":false},"moveSpeed":3,"moveType":0,"priorityType":1,"stepAnime":false,"through":false,"trigger":0,"walkAnime":true},{"conditions":{"actorId":1,"actorValid":false,"itemId":1,"itemValid":false,"selfSwitchCh":"D","selfSwitchValid":true,"switch1Id":102,"switch1Valid":true,"switch2Id":1,"switch2Valid":false,"variableId":1,"variableValid":false,"variableValue":0},"directionFix":false,"image":{"tileId":0,"characterName":"People/04-Mage","direction":2,"pattern":0,"characterIndex":0},"list":[{"code":111,"indent":0,"parameters":[0,124,1]},{"code":121,"indent":1,"parameters":[124,124,0]},{"code":122,"indent":1,"parameters":[182,182,1,0,1]},{"code":357,"indent":1,"parameters":["CGMZ_PictureGallery","Discover Picture","Discover Picture",{"id":" | Z1: =D1 -> Abba | AA1: ,discover":"true"}]},{"code":657,"indent":1,"parameters":["id = | AB1: =D1 -> Abba | AC1: ]},{code":657,"indent":1,"parameters":["discover = true"]},{"code":357,"indent":1,"parameters":["CGMZ_Reputations","gainRep","Gain Reputation",{"name":"Cognet Points","category":"Social","amount":"10"}]},{"code":657,"indent":1,"parameters":["Reputation Name = Cognet Points"]},{"code":657,"indent":1,"parameters":["Reputation Category = Social"]},{"code":657,"indent":1,"parameters":["Amount = 10"]},{"code":0,"indent":1,"parameters":[]},{"code":412,"indent":0,"parameters":[]},{"code":231,"indent":0,"parameters":[100,"fes_pictures_004_4_1",0,0,240,88,100,100,255,0]},{"code":230,"indent":0,"parameters":[200]},{"code":235,"indent":0,"parameters":[100]},{"code":123,"indent":0,"parameters":["D",1]},{"code":0,"indent":0,"parameters":[]}],"moveFrequency":3,"moveRoute":{"list":[{"code":0,"parameters":[]}],"repeat":true,"skippable":false,"wait":false},"moveSpeed":3,"moveType":0,"priorityType":1,"stepAnime":false,"through":false,"trigger":4,"walkAnime":true}],"x": | AD1: 10 | AE1: ,"y": | AF1: 2 | AG1: },
A2: {"id": | B2: 52 | C2: ,"name":" | D2: ='NPCs bc45871df08a46b3ae7d8e083e'!A4 -> Abbey | E2: ,note":"","pages":[{"conditions":{"actorId":1,"actorValid":false,"itemId":1,"itemValid":false,"selfSwitchCh":"A","selfSwitchValid":false,"switch1Id":1,"switch1Valid":false,"switch2Id":1,"switch2Valid":false,"variableId":1,"variableValid":false,"variableValue":0},"directionFix":true,"image":{"tileId":0,"characterName":"People/04-Mage","direction":2,"pattern":0,"characterIndex":0},"list":[{"code":108,"indent":0,"parameters":["iconOnMinimap:minimapIcon_Evil7"]},{"code":108,"indent":0,"parameters":["<ABS: | F2: =B2 -> 52 | G2: >"]},{"code":108,"indent":0,"parameters":["<label: NPC>"]},{"code":357,"indent":0,"parameters":["Alpha_ABSZ","ABSEventSettings","ABS Enemy Configurate",{"MainGroup":"","viewRadius":"5","returnRadius":"12","noMoveInBattle":"false","noApproach":"true","onDeath":"","onSeeTarget":"","onHit":"","expVar":"0","autoExp":"false","notAgressive":"true","teamId":"2","onDeathVar":"0","saveHp":"false","MapGroup":"","shatterEffect":"true","deadSwitch":"0","eraseOnDead":"true","heavy":"false","weaponMotionType":"0","lootDropOnDeath":"false","VisualGroup":"","UIInfo":"true","faceName":"","faceIndex":"0","miniHpGaugeStyle":"","AnimationGroup":"","hitAnimationId":"1"}]},{"code":657,"indent":0,"parameters":["Main Group = "]},{"code":657,"indent":0,"parameters":["View Radius = 5"]},{"code":657,"indent":0,"parameters":["Return Radius = 12"]},{"code":657,"indent":0,"parameters":["No Move in Battle = false"]},{"code":657,"indent":0,"parameters":["No Approach Target = true"]},{"code":657,"indent":0,"parameters":["On Death = "]},{"code":657,"indent":0,"parameters":["On See Target = "]},{"code":657,"indent":0,"parameters":["On Hit = "]},{"code":657,"indent":0,"parameters":["Exp Variable = 0"]},{"code":657,"indent":0,"parameters":["Auto Exp = false"]},{"code":657,"indent":0,"parameters":["Not Agressive = true"]},{"code":657,"indent":0,"parameters":["Team ID = 2"]},{"code":657,"indent":0,"parameters":["Death Variable = 0"]},{"code":657,"indent":0,"parameters":["Save HP = false"]},{"code":657,"indent":0,"parameters":["Map Group = "]},{"code":657,"indent":0,"parameters":["Shatter Effect? = true"]},{"code":657,"indent":0,"parameters":["Dead Switch = 0"]},{"code":657,"indent":0,"parameters":["Erase on Dead? = true"]},{"code":657,"indent":0,"parameters":["Is heavy = false"]},{"code":657,"indent":0,"parameters":["Weapon Motion Type = 0"]},{"code":657,"indent":0,"parameters":["Drop Loot = false"]},{"code":657,"indent":0,"parameters":["Visual Group = "]},{"code":657,"indent":0,"parameters":["Show UI Info? = true"]},{"code":657,"indent":0,"parameters":["Face Name = "]},{"code":657,"indent":0,"parameters":["Face Index = 0"]},{"code":657,"indent":0,"parameters":["Mini HP Gauge Style = "]},{"code":657,"indent":0,"parameters":["Animation Group = "]},{"code":657,"indent":0,"parameters":["Hit Animation = 1"]},{"code":101,"indent":0,"parameters":["ds_face01-02",5,0,2,""]},{"code":401,"indent":0,"parameters":["Hi I'm | H2: =D2 -> Abbey | I2: ."]},{"code":0,"indent":0,"parameters":[]}],"moveFrequency":3,"moveRoute":{"list":[{"code":0,"parameters":[]}],"repeat":true,"skippable":false,"wait":false},"moveSpeed":3,"moveType":0,"priorityType":1,"stepAnime":false,"through":false,"trigger":0,"walkAnime":true},{"conditions":{"actorId":1,"actorValid":false,"itemId":1,"itemValid":false,"selfSwitchCh":"A","selfSwitchValid":true,"switch1Id":1,"switch1Valid":false,"switch2Id":1,"switch2Valid":false,"variableId":1,"variableValid":false,"variableValue":0},"directionFix":false,"image":{"tileId":0,"characterName":"People/04-Mage","direction":2,"pattern":0,"characterIndex":0},"list":[{"code":108,"indent":0,"parameters":["iconOnMinimap:minimapIcon_Evil7"]},{"code":108,"indent":0,"parameters":["<ABS: | J2: =B2 -> 52 | K2: >"]},{"code":108,"indent":0,"parameters":["<label: NPC>"]},{"code":357,"indent":0,"parameters":["Alpha_ABSZ","ABSEventSettings","ABS Enemy Configurate",{"MainGroup":"","viewRadius":"5","returnRadius":"12","noMoveInBattle":"false","noApproach":"true","onDeath":"","onSeeTarget":"","onHit":"","expVar":"0","autoExp":"false","notAgressive":"true","teamId":"2","onDeathVar":"0","saveHp":"false","MapGroup":"","shatterEffect":"true","deadSwitch":"0","eraseOnDead":"true","heavy":"false","weaponMotionType":"0","lootDropOnDeath":"false","VisualGroup":"","UIInfo":"true","faceName":"","faceIndex":"0","miniHpGaugeStyle":"","AnimationGroup":"","hitAnimationId":"1"}]},{"code":657,"indent":0,"parameters":["Main Group = "]},{"code":657,"indent":0,"parameters":["View Radius = 5"]},{"code":657,"indent":0,"parameters":["Return Radius = 12"]},{"code":657,"indent":0,"parameters":["No Move in Battle = false"]},{"code":657,"indent":0,"parameters":["No Approach Target = true"]},{"code":657,"indent":0,"parameters":["On Death = "]},{"code":657,"indent":0,"parameters":["On See Target = "]},{"code":657,"indent":0,"parameters":["On Hit = "]},{"code":657,"indent":0,"parameters":["Exp Variable = 0"]},{"code":657,"indent":0,"parameters":["Auto Exp = false"]},{"code":657,"indent":0,"parameters":["Not Agressive = true"]},{"code":657,"indent":0,"parameters":["Team ID = 2"]},{"code":657,"indent":0,"parameters":["Death Variable = 0"]},{"code":657,"indent":0,"parameters":["Save HP = false"]},{"code":657,"indent":0,"parameters":["Map Group = "]},{"code":657,"indent":0,"parameters":["Shatter Effect? = true"]},{"code":657,"indent":0,"parameters":["Dead Switch = 0"]},{"code":657,"indent":0,"parameters":["Erase on Dead? = true"]},{"code":657,"indent":0,"parameters":["Is heavy = false"]},{"code":657,"indent":0,"parameters":["Weapon Motion Type = 0"]},{"code":657,"indent":0,"parameters":["Drop Loot = false"]},{"code":657,"indent":0,"parameters":["Visual Group = "]},{"code":657,"indent":0,"parameters":["Show UI Info? = true"]},{"code":657,"indent":0,"parameters":["Face Name = "]},{"code":657,"indent":0,"parameters":["Face Index = 0"]},{"code":657,"indent":0,"parameters":["Mini HP Gauge Style = "]},{"code":657,"indent":0,"parameters":["Animation Group = "]},{"code":657,"indent":0,"parameters":["Hit Animation = 1"]},{"code":101,"indent":0,"parameters":["People4",5,0,2,""]},{"code":401,"indent":0,"parameters":["Hi I'm | L2: =D2 -> Abbey | M2: ."]},{"code":0,"indent":0,"parameters":[]}],"moveFrequency":3,"moveRoute":{"list":[{"code":0,"parameters":[]}],"repeat":true,"skippable":false,"wait":false},"moveSpeed":3,"moveType":0,"priorityType":1,"stepAnime":false,"through":false,"trigger":0,"walkAnime":true},{"conditions":{"actorId":1,"actorValid":false,"itemId":1,"itemValid":false,"selfSwitchCh":"B","selfSwitchValid":true,"switch1Id":1,"switch1Valid":false,"switch2Id":1,"switch2Valid":false,"variableId":1,"variableValid":false,"variableValue":0},"directionFix":false,"image":{"tileId":0,"characterName":"People/04-Mage","direction":2,"pattern":0,"characterIndex":0},"list":[{"code":108,"indent":0,"parameters":["iconOnMinimap:minimapIcon_Evil7"]},{"code":108,"indent":0,"parameters":["<ABS: | N2: =B2 -> 52 | O2: >"]},{"code":108,"indent":0,"parameters":["<label: NPC>"]},{"code":357,"indent":0,"parameters":["Alpha_ABSZ","ABSEventSettings","ABS Enemy Configurate",{"MainGroup":"","viewRadius":"5","returnRadius":"12","noMoveInBattle":"false","noApproach":"true","onDeath":"","onSeeTarget":"","onHit":"","expVar":"0","autoExp":"false","notAgressive":"true","teamId":"2","onDeathVar":"0","saveHp":"false","MapGroup":"","shatterEffect":"true","deadSwitch":"0","eraseOnDead":"true","heavy":"false","weaponMotionType":"0","lootDropOnDeath":"false","VisualGroup":"","UIInfo":"true","faceName":"","faceIndex":"0","miniHpGaugeStyle":"","AnimationGroup":"","hitAnimationId":"1"}]},{"code":657,"indent":0,"parameters":["Main Group = "]},{"code":657,"indent":0,"parameters":["View Radius = 5"]},{"code":657,"indent":0,"parameters":["Return Radius = 12"]},{"code":657,"indent":0,"parameters":["No Move in Battle = false"]},{"code":657,"indent":0,"parameters":["No Approach Target = true"]},{"code":657,"indent":0,"parameters":["On Death = "]},{"code":657,"indent":0,"parameters":["On See Target = "]},{"code":657,"indent":0,"parameters":["On Hit = "]},{"code":657,"indent":0,"parameters":["Exp Variable = 0"]},{"code":657,"indent":0,"parameters":["Auto Exp = false"]},{"code":657,"indent":0,"parameters":["Not Agressive = true"]},{"code":657,"indent":0,"parameters":["Team ID = 2"]},{"code":657,"indent":0,"parameters":["Death Variable = 0"]},{"code":657,"indent":0,"parameters":["Save HP = false"]},{"code":657,"indent":0,"parameters":["Map Group = "]},{"code":657,"indent":0,"parameters":["Shatter Effect? = true"]},{"code":657,"indent":0,"parameters":["Dead Switch = 0"]},{"code":657,"indent":0,"parameters":["Erase on Dead? = true"]},{"code":657,"indent":0,"parameters":["Is heavy = false"]},{"code":657,"indent":0,"parameters":["Weapon Motion Type = 0"]},{"code":657,"indent":0,"parameters":["Drop Loot = false"]},{"code":657,"indent":0,"parameters":["Visual Group = "]},{"code":657,"indent":0,"parameters":["Show UI Info? = true"]},{"code":657,"indent":0,"parameters":["Face Name = "]},{"code":657,"indent":0,"parameters":["Face Index = 0"]},{"code":657,"indent":0,"parameters":["Mini HP Gauge Style = "]},{"code":657,"indent":0,"parameters":["Animation Group = "]},{"code":657,"indent":0,"parameters":["Hit Animation = 1"]},{"code":101,"indent":0,"parameters":["People4",5,0,2,""]},{"code":401,"indent":0,"parameters":["Hi I'm | P2: =D2 -> Abbey | Q2: ."]},{"code":0,"indent":0,"parameters":[]}],"moveFrequency":3,"moveRoute":{"list":[{"code":0,"parameters":[]}],"repeat":true,"skippable":false,"wait":false},"moveSpeed":3,"moveType":0,"priorityType":1,"stepAnime":false,"through":false,"trigger":0,"walkAnime":true},{"conditions":{"actorId":1,"actorValid":false,"itemId":1,"itemValid":false,"selfSwitchCh":"C","selfSwitchValid":true,"switch1Id":1,"switch1Valid":false,"switch2Id":1,"switch2Valid":false,"variableId":1,"variableValid":false,"variableValue":0},"directionFix":false,"image":{"tileId":0,"characterName":"People/04-Mage","direction":2,"pattern":0,"characterIndex":0},"list":[{"code":108,"indent":0,"parameters":["iconOnMinimap:minimapIcon_Evil7"]},{"code":108,"indent":0,"parameters":["<ABS: | R2: =B2 -> 52 | S2: >"]},{"code":108,"indent":0,"parameters":["<label: NPC>"]},{"code":357,"indent":0,"parameters":["Alpha_ABSZ","ABSEventSettings","ABS Enemy Configurate",{"MainGroup":"","viewRadius":"5","returnRadius":"12","noMoveInBattle":"false","noApproach":"true","onDeath":"","onSeeTarget":"","onHit":"","expVar":"0","autoExp":"false","notAgressive":"true","teamId":"2","onDeathVar":"0","saveHp":"false","MapGroup":"","shatterEffect":"true","deadSwitch":"0","eraseOnDead":"true","heavy":"false","weaponMotionType":"0","lootDropOnDeath":"false","VisualGroup":"","UIInfo":"true","faceName":"","faceIndex":"0","miniHpGaugeStyle":"","AnimationGroup":"","hitAnimationId":"1"}]},{"code":657,"indent":0,"parameters":["Main Group = "]},{"code":657,"indent":0,"parameters":["View Radius = 5"]},{"code":657,"indent":0,"parameters":["Return Radius = 12"]},{"code":657,"indent":0,"parameters":["No Move in Battle = false"]},{"code":657,"indent":0,"parameters":["No Approach Target = true"]},{"code":657,"indent":0,"parameters":["On Death = "]},{"code":657,"indent":0,"parameters":["On See Target = "]},{"code":657,"indent":0,"parameters":["On Hit = "]},{"code":657,"indent":0,"parameters":["Exp Variable = 0"]},{"code":657,"indent":0,"parameters":["Auto Exp = false"]},{"code":657,"indent":0,"parameters":["Not Agressive = true"]},{"code":657,"indent":0,"parameters":["Team ID = 2"]},{"code":657,"indent":0,"parameters":["Death Variable = 0"]},{"code":657,"indent":0,"parameters":["Save HP = false"]},{"code":657,"indent":0,"parameters":["Map Group = "]},{"code":657,"indent":0,"parameters":["Shatter Effect? = true"]},{"code":657,"indent":0,"parameters":["Dead Switch = 0"]},{"code":657,"indent":0,"parameters":["Erase on Dead? = true"]},{"code":657,"indent":0,"parameters":["Is heavy = false"]},{"code":657,"indent":0,"parameters":["Weapon Motion Type = 0"]},{"code":657,"indent":0,"parameters":["Drop Loot = false"]},{"code":657,"indent":0,"parameters":["Visual Group = "]},{"code":657,"indent":0,"parameters":["Show UI Info? = true"]},{"code":657,"indent":0,"parameters":["Face Name = "]},{"code":657,"indent":0,"parameters":["Face Index = 0"]},{"code":657,"indent":0,"parameters":["Mini HP Gauge Style = "]},{"code":657,"indent":0,"parameters":["Animation Group = "]},{"code":657,"indent":0,"parameters":["Hit Animation = 1"]},{"code":101,"indent":0,"parameters":["People4",5,0,2,""]},{"code":401,"indent":0,"parameters":["Hi I'm | T2: =D2 -> Abbey | U2: ."]},{"code":0,"indent":0,"parameters":[]}],"moveFrequency":3,"moveRoute":{"list":[{"code":0,"parameters":[]}],"repeat":true,"skippable":false,"wait":false},"moveSpeed":3,"moveType":0,"priorityType":1,"stepAnime":false,"through":false,"trigger":0,"walkAnime":true},{"conditions":{"actorId":1,"actorValid":false,"itemId":1,"itemValid":false,"selfSwitchCh":"D","selfSwitchValid":true,"switch1Id":1,"switch1Valid":false,"switch2Id":1,"switch2Valid":false,"variableId":1,"variableValid":false,"variableValue":0},"directionFix":false,"image":{"tileId":0,"characterName":"People/04-Mage","direction":2,"pattern":0,"characterIndex":0},"list":[{"code":108,"indent":0,"parameters":["iconOnMinimap:minimapIcon_Evil7"]},{"code":108,"indent":0,"parameters":["<ABS: | V2: =B2 -> 52 | W2: >"]},{"code":108,"indent":0,"parameters":["<label: NPC>"]},{"code":357,"indent":0,"parameters":["Alpha_ABSZ","ABSEventSettings","ABS Enemy Configurate",{"MainGroup":"","viewRadius":"5","returnRadius":"12","noMoveInBattle":"false","noApproach":"true","onDeath":"","onSeeTarget":"","onHit":"","expVar":"0","autoExp":"false","notAgressive":"true","teamId":"2","onDeathVar":"0","saveHp":"false","MapGroup":"","shatterEffect":"true","deadSwitch":"0","eraseOnDead":"true","heavy":"false","weaponMotionType":"0","lootDropOnDeath":"false","VisualGroup":"","UIInfo":"true","faceName":"","faceIndex":"0","miniHpGaugeStyle":"","AnimationGroup":"","hitAnimationId":"1"}]},{"code":657,"indent":0,"parameters":["Main Group = "]},{"code":657,"indent":0,"parameters":["View Radius = 5"]},{"code":657,"indent":0,"parameters":["Return Radius = 12"]},{"code":657,"indent":0,"parameters":["No Move in Battle = false"]},{"code":657,"indent":0,"parameters":["No Approach Target = true"]},{"code":657,"indent":0,"parameters":["On Death = "]},{"code":657,"indent":0,"parameters":["On See Target = "]},{"code":657,"indent":0,"parameters":["On Hit = "]},{"code":657,"indent":0,"parameters":["Exp Variable = 0"]},{"code":657,"indent":0,"parameters":["Auto Exp = false"]},{"code":657,"indent":0,"parameters":["Not Agressive = true"]},{"code":657,"indent":0,"parameters":["Team ID = 2"]},{"code":657,"indent":0,"parameters":["Death Variable = 0"]},{"code":657,"indent":0,"parameters":["Save HP = false"]},{"code":657,"indent":0,"parameters":["Map Group = "]},{"code":657,"indent":0,"parameters":["Shatter Effect? = true"]},{"code":657,"indent":0,"parameters":["Dead Switch = 0"]},{"code":657,"indent":0,"parameters":["Erase on Dead? = true"]},{"code":657,"indent":0,"parameters":["Is heavy = false"]},{"code":657,"indent":0,"parameters":["Weapon Motion Type = 0"]},{"code":657,"indent":0,"parameters":["Drop Loot = false"]},{"code":657,"indent":0,"parameters":["Visual Group = "]},{"code":657,"indent":0,"parameters":["Show UI Info? = true"]},{"code":657,"indent":0,"parameters":["Face Name = "]},{"code":657,"indent":0,"parameters":["Face Index = 0"]},{"code":657,"indent":0,"parameters":["Mini HP Gauge Style = "]},{"code":657,"indent":0,"parameters":["Animation Group = "]},{"code":657,"indent":0,"parameters":["Hit Animation = 1"]},{"code":101,"indent":0,"parameters":["People4",5,0,2,""]},{"code":401,"indent":0,"parameters":["Hi I'm | X2: =D2 -> Abbey | Y2: ."]},{"code":0,"indent":0,"parameters":[]}],"moveFrequency":3,"moveRoute":{"list":[{"code":0,"parameters":[]}],"repeat":true,"skippable":false,"wait":false},"moveSpeed":3,"moveType":0,"priorityType":1,"stepAnime":false,"through":false,"trigger":0,"walkAnime":true},{"conditions":{"actorId":1,"actorValid":false,"itemId":1,"itemValid":false,"selfSwitchCh":"D","selfSwitchValid":true,"switch1Id":102,"switch1Valid":true,"switch2Id":1,"switch2Valid":false,"variableId":1,"variableValid":false,"variableValue":0},"directionFix":false,"image":{"tileId":0,"characterName":"People/04-Mage","direction":2,"pattern":0,"characterIndex":0},"list":[{"code":111,"indent":0,"parameters":[0,124,1]},{"code":121,"indent":1,"parameters":[124,124,0]},{"code":122,"indent":1,"parameters":[182,182,1,0,1]},{"code":357,"indent":1,"parameters":["CGMZ_PictureGallery","Discover Picture","Discover Picture",{"id":" | Z2: =D2 -> Abbey | AA2: ,discover":"true"}]},{"code":657,"indent":1,"parameters":["id = | AB2: =D2 -> Abbey | AC2: ]},{code":657,"indent":1,"parameters":["discover = true"]},{"code":357,"indent":1,"parameters":["CGMZ_Reputations","gainRep","Gain Reputation",{"name":"Cognet Points","category":"Social","amount":"10"}]},{"code":657,"indent":1,"parameters":["Reputation Name = Cognet Points"]},{"code":657,"indent":1,"parameters":["Reputation Category = Social"]},{"code":657,"indent":1,"parameters":["Amount = 10"]},{"code":0,"indent":1,"parameters":[]},{"code":412,"indent":0,"parameters":[]},{"code":231,"indent":0,"parameters":[100,"fes_pictures_004_4_1",0,0,240,88,100,100,255,0]},{"code":230,"indent":0,"parameters":[200]},{"code":235,"indent":0,"parameters":[100]},{"code":123,"indent":0,"parameters":["D",1]},{"code":0,"indent":0,"parameters":[]}],"moveFrequency":3,"moveRoute":{"list":[{"code":0,"parameters":[]}],"repeat":true,"skippable":false,"wait":false},"moveSpeed":3,"moveType":0,"priorityType":1,"stepAnime":false,"through":false,"trigger":4,"walkAnime":true}],"x": | AD2: =IF(AD1+1<=19,AD1+1,IF(AD1+1>=20,0,AD1+1)) -> 11 | AE2: ,"y": | AF2: =IF(AD2=0,AF1+1,AF1) -> 2 | AG2: },
